Workbook
Name COA_CLASS: '10 Chart of Accounts'!$D$5:$D$300
Name COA_COMPANY: '10 Chart of Accounts'!$E$5:$E$300
Name COA_LEDGER: '10 Chart of Accounts'!$A$5:$A$300
Name COA_OVERHEAD: '10 Chart of Accounts'!$F$5:$F$300
Name OLD_PROJECTS: '01 Settings'!$A$21:$A$300
Name SEG_DATE: '01 Settings'!$B$14
Name TXN_ADJ: '11 Transaction Master'!$T$6:$T$100005
Name TXN_AMOUNT: '11 Transaction Master'!$I$6:$I$100005
Name TXN_BAL: '11 Transaction Master'!$X$6:$X$100005
Name TXN_BANK: '11 Transaction Master'!$O$6:$O$100005
Name TXN_CASH: '11 Transaction Master'!$P$6:$P$100005
Name TXN_CREDIT: '11 Transaction Master'!$H$6:$H$100005
Name TXN_CUSTOMER: '11 Transaction Master'!$L$6:$L$100005
Name TXN_DATE: '11 Transaction Master'!$A$6:$A$100005
Name TXN_DEBIT: '11 Transaction Master'!$G$6:$G$100005
Name TXN_FLAG: '11 Transaction Master'!$S$6:$S$100005
Name TXN_GST: '11 Transaction Master'!$J$6:$J$100005
Name TXN_LEDGER: '11 Transaction Master'!$D$6:$D$100005
Name TXN_NEWPROJ: '11 Transaction Master'!$R$6:$R$100005
Name TXN_OLDPROJ: '11 Transaction Master'!$Q$6:$Q$100005
Name TXN_PARTY: '11 Transaction Master'!$E$6:$E$100005
Name TXN_PAYMODE: '11 Transaction Master'!$N$6:$N$100005
Name TXN_PROJECT: '11 Transaction Master'!$K$6:$K$100005
Name TXN_RECOV: '11 Transaction Master'!$U$6:$U$100005
Name TXN_SUGFLAG: '11 Transaction Master'!$V$6:$V$100005
Name TXN_SUPPLIER: '11 Transaction Master'!$M$6:$M$100005
Name TXN_VNO: '11 Transaction Master'!$B$6:$B$100005

Sheet 01 Settings
A1: SETTINGS & MASTER CONTROL
A2: Appletree Interiors — Business Segregation Workbook
A4: COMPANY NAMES
A5: Old Company (pre-segregation entity) | B5: Appletree Interiors
A6: New Company (JV execution entity) | B6: Appletree Interiors Pvt Ltd
A7: Ownership split | B7: 50% Appletree / 50% Stories
A9: KEY DATES
A10: Old Company cut-off (ongoing projects valued) | B10: 2025-12-31
A11: New Company incorporation date | B11: 2026-01-01
A12: Mixed-books period start | B12: 2026-01-01
A13: Mixed-books period end | B13: 2026-07-11
A14: SEGREGATION DATE (books become independent) | B14: 2026-07-11
A16: OPENING BALANCE — ONGOING PROJECTS AS ON 31-DEC-2025 (belongs to OLD COMPANY per Rule 1)
A17: Total value of ongoing projects (WIP + Revenue base) | B17: 12586031
A19: OLD PROJECTS MASTER (add one row per ongoing project as on 31-Dec-2025)
A20: Project Name | B20: Customer | C20: Value as on 31-Dec-2025 | D20: Status
A28: GST RATES
A29: Exempt | B29: 0
A30: GST 5% | B30: 0.05
A31: GST 12% | B31: 0.12
A32: GST 18% | B32: 0.18
A33: GST 28% | B33: 0.28
A36: ALLOCATION RULES (business rules encoded — see full text for detail)
A37: RULE 1: Revenue, Receivables, Advances and Profit on the ongoing (31-Dec-2025) projects belong to the OLD COMPANY.
A38: RULE 2: New Company executes those projects only as an EXECUTION AGENCY.
A39: RULE 3: Execution is at ACTUAL COST ONLY — no markup, no management fee, no overhead recovery.
A40: RULE 4: ALL office overhead from 01-Jan-2026 onward belongs 100% to the NEW COMPANY. Old Company bears ZERO overhead after that date.
A41: RULE 5: Only DIRECT PROJECT COST (material, site labour, subcontract, transport, project-specific expense) incurred by New Co for Old projects is recoverable from Old Co.
A42: RULE 6: Raw material stock transferred Old->New is booked as Old Co Stock Sale / New Co Stock Purchase (sheet 21).
A43: RULE 7: Segregation date 11-Jul-2026 — books fully independent from that date.
A44: SHARED flag: minimal by design (Rule 4 removes most sharing). Where it exists, sheet 26 (Adjustment Journals) shows a recommended split — never auto-applied.

Sheet 02 Import DayBook
A1: IMPORT DAYBOOK — RAW PASTE ZONE
A2: Paste the Tally export below the header row exactly as exported. Do NOT edit values here.
A4: Date | B4: Voucher No | C4: Voucher Type | D4: Ledger | E4: Party | F4: Narration | G4: Debit | H4: Credit | I4: Amount | J4: GST Amount | K4: Reference
A5: e.g. Date
A108: HOW TO USE THIS SHEET
A109: 1. Export the corresponding report from Tally (Gateway of Tally > Display/Reports > Export > Excel).
A110: 2. Paste as VALUES starting at the row directly below the header (row 5), keeping column order.
A111: 3. This is a raw staging area only — no formulas live here. All processing happens in sheet 11 (Transaction Master).
A112: 4. Extend the table (drag the bottom-right corner) if you have more rows than currently sized.

Sheet 03 Import Ledger
A1: IMPORT LEDGER — RAW PASTE ZONE
A2: Paste the Tally export below the header row exactly as exported. Do NOT edit values here.
A4: Ledger Name | B4: Group | C4: Date | D4: Particulars | E4: Voucher Type | F4: Debit | G4: Credit | H4: Balance
A5: e.g. Ledger Name
A108: HOW TO USE THIS SHEET
A109: 1. Export the corresponding report from Tally (Gateway of Tally > Display/Reports > Export > Excel).
A110: 2. Paste as VALUES starting at the row directly below the header (row 5), keeping column order.
A111: 3. This is a raw staging area only — no formulas live here. All processing happens in sheet 11 (Transaction Master).
A112: 4. Extend the table (drag the bottom-right corner) if you have more rows than currently sized.

Sheet 04 Import TrialBalance
A1: IMPORT TRIALBALANCE — RAW PASTE ZONE
A2: Paste the Tally export below the header row exactly as exported. Do NOT edit values here.
A4: Ledger Name | B4: Group | C4: Opening Debit | D4: Opening Credit | E4: Debit | F4: Credit | G4: Closing Debit | H4: Closing Credit
A5: e.g. Ledger Name
A108: HOW TO USE THIS SHEET
A109: 1. Export the corresponding report from Tally (Gateway of Tally > Display/Reports > Export > Excel).
A110: 2. Paste as VALUES starting at the row directly below the header (row 5), keeping column order.
A111: 3. This is a raw staging area only — no formulas live here. All processing happens in sheet 11 (Transaction Master).
A112: 4. Extend the table (drag the bottom-right corner) if you have more rows than currently sized.

Sheet 05 Import Stock
A1: IMPORT STOCK — RAW PASTE ZONE
A2: Paste the Tally export below the header row exactly as exported. Do NOT edit values here.
A4: Item Name | B4: Group | C4: Unit | D4: Opening Qty | E4: Opening Value | F4: Inward Qty | G4: Inward Value | H4: Outward Qty | I4: Outward Value | J4: Closing Qty | K4: Closing Value
A5: e.g. Item Name
A108: HOW TO USE THIS SHEET
A109: 1. Export the corresponding report from Tally (Gateway of Tally > Display/Reports > Export > Excel).
A110: 2. Paste as VALUES starting at the row directly below the header (row 5), keeping column order.
A111: 3. This is a raw staging area only — no formulas live here. All processing happens in sheet 11 (Transaction Master).
A112: 4. Extend the table (drag the bottom-right corner) if you have more rows than currently sized.

Sheet 06 Import Receivables
A1: IMPORT RECEIVABLES — RAW PASTE ZONE
A2: Paste the Tally export below the header row exactly as exported. Do NOT edit values here.
A4: Customer | B4: Voucher No | C4: Date | D4: Due Date | E4: Bill Amount | F4: Amount Received | G4: Balance Due | H4: Project
A5: e.g. Customer
A108: HOW TO USE THIS SHEET
A109: 1. Export the corresponding report from Tally (Gateway of Tally > Display/Reports > Export > Excel).
A110: 2. Paste as VALUES starting at the row directly below the header (row 5), keeping column order.
A111: 3. This is a raw staging area only — no formulas live here. All processing happens in sheet 11 (Transaction Master).
A112: 4. Extend the table (drag the bottom-right corner) if you have more rows than currently sized.

Sheet 07 Import Payables
A1: IMPORT PAYABLES — RAW PASTE ZONE
A2: Paste the Tally export below the header row exactly as exported. Do NOT edit values here.
A4: Supplier | B4: Voucher No | C4: Date | D4: Due Date | E4: Bill Amount | F4: Amount Paid | G4: Balance Due | H4: Project
A5: e.g. Supplier
A108: HOW TO USE THIS SHEET
A109: 1. Export the corresponding report from Tally (Gateway of Tally > Display/Reports > Export > Excel).
A110: 2. Paste as VALUES starting at the row directly below the header (row 5), keeping column order.
A111: 3. This is a raw staging area only — no formulas live here. All processing happens in sheet 11 (Transaction Master).
A112: 4. Extend the table (drag the bottom-right corner) if you have more rows than currently sized.

Sheet 08 Import BankBook
A1: IMPORT BANKBOOK — RAW PASTE ZONE
A2: Paste the Tally export below the header row exactly as exported. Do NOT edit values here.
A4: Date | B4: Bank Ledger | C4: Voucher No | D4: Particulars | E4: Voucher Type | F4: Debit (Deposit) | G4: Credit (Withdrawal) | H4: Balance
A5: e.g. Date
A108: HOW TO USE THIS SHEET
A109: 1. Export the corresponding report from Tally (Gateway of Tally > Display/Reports > Export > Excel).
A110: 2. Paste as VALUES starting at the row directly below the header (row 5), keeping column order.
A111: 3. This is a raw staging area only — no formulas live here. All processing happens in sheet 11 (Transaction Master).
A112: 4. Extend the table (drag the bottom-right corner) if you have more rows than currently sized.

Sheet 09 Import CashBook
A1: IMPORT CASHBOOK — RAW PASTE ZONE
A2: Paste the Tally export below the header row exactly as exported. Do NOT edit values here.
A4: Date | B4: Voucher No | C4: Particulars | D4: Voucher Type | E4: Debit (Receipt) | F4: Credit (Payment) | G4: Balance
A5: e.g. Date
A108: HOW TO USE THIS SHEET
A109: 1. Export the corresponding report from Tally (Gateway of Tally > Display/Reports > Export > Excel).
A110: 2. Paste as VALUES starting at the row directly below the header (row 5), keeping column order.
A111: 3. This is a raw staging area only — no formulas live here. All processing happens in sheet 11 (Transaction Master).
A112: 4. Extend the table (drag the bottom-right corner) if you have more rows than currently sized.

Sheet 10 Chart of Accounts
A1: CHART OF ACCOUNTS MAPPING
A2: Every ledger used in Tally must appear here exactly once. This drives classification everywhere else.
A4: Ledger Name | B4: Group | C4: Nature | D4: Classification | E4: Default Company Assignment | F4: Overhead? (Y/N) | G4: Notes
A5: Sales - Interior Projects | B5: Sales Accounts | C5: Income | D5: Income | E5: Old Company | F5: N | G5: Rule 1: all revenue on ongoing projects stays with Old Co
A6: Site Material Purchase | B6: Purchase Accounts | C6: Expense | D6: Direct Cost | E6: Split by Flag | F6: N | G6: Direct project cost — recoverable from Old Co if for Old project (Rule 5)
A7: Site Labour Charges | B7: Direct Expenses | C7: Expense | D7: Direct Cost | E7: Split by Flag | F7: N | G7: Direct project cost — recoverable
A8: Subcontract Charges | B8: Direct Expenses | C8: Expense | D8: Direct Cost | E8: Split by Flag | F8: N | G8: Direct project cost — recoverable
A9: Site Transport | B9: Direct Expenses | C9: Expense | D9: Direct Cost | E9: Split by Flag | F9: N | G9: Direct project cost — recoverable
A10: Office Rent | B10: Indirect Expenses | C10: Expense | D10: Indirect Cost | E10: New Company | F10: Y | G10: Rule 4: 100% New Co, never recoverable from Old Co
A11: Office Salary | B11: Indirect Expenses | C11: Expense | D11: Indirect Cost | E11: New Company | F11: Y | G11: Rule 4
A12: Admin Salary | B12: Indirect Expenses | C12: Expense | D12: Indirect Cost | E12: New Company | F12: Y | G12: Rule 4
A13: Electricity Charges | B13: Indirect Expenses | C13: Expense | D13: Indirect Cost | E13: New Company | F13: Y | G13: Rule 4
A14: Internet & Telephone | B14: Indirect Expenses | C14: Expense | D14: Indirect Cost | E14: New Company | F14: Y | G14: Rule 4
A15: Fuel Expenses | B15: Indirect Expenses | C15: Expense | D15: Indirect Cost | E15: New Company | F15: Y | G15: Rule 4
... A22: Sundry Debtors | B22: Sundry Debtors | C22: Asset | D22: Asset | E22: Old Company | F22: N | G22: Receivables on Old projects (Rule 1)
A23: Sundry Creditors | B23: Sundry Creditors | C23: Liability | D23: Liability | E23: Split by Flag | F23: N
A24: Customer Advance | B24: Current Liabilities | C24: Liability | D24: Liability | E24: Old Company | F24: N | G24: Rule 1
A25: HDFC Bank - Old Co | B25: Bank Accounts | C25: Asset | D25: Bank | E25: Old Company | F25: N
A26: HDFC Bank - New Co | B26: Bank Accounts | C26: Asset | D26: Bank | E26: New Company | F26: N
A27: Cash | B27: Cash-in-Hand | C27: Asset | D27: Cash | E27: Split by Flag | F27: N
A28: Raw Material Stock | B28: Stock-in-Hand | C28: Asset | D28: Stock | E28: Split by Flag | F28: N | G28: Rule 6: transfer = Old sale / New purchase
A29: Output CGST/SGST/IGST | B29: Duties & Taxes | C29: Liability | D29: GST | E29: Split by Flag | F29: N
A30: Input CGST/SGST/IGST | B30: Duties & Taxes | C30: Asset | D30: GST | E30: Split by Flag | F30: N
A31: Bank Loan | B31: Loans (Liability) | C31: Liability | D31: Loan | E31: Split by Flag | F31: N
A32: Capital Account | B32: Capital Account | C32: Liability | D32: Capital | E32: Split by Flag | F32: N
A33: Intercompany - Old Co A/c | B33: Intercompany | C33: Asset/Liability | D33: Intercompany | E33: Both | F33: N | G33: Auto-populated mirror of sheet 12
A34: Intercompany - New Co A/c | B34: Intercompany | C34: Asset/Liability | D34: Intercompany | E34: Both | F34: N | G34: Auto-populated mirror of sheet 12
A37: HOW TO USE THIS SHEET
A38: Add EVERY ledger from your Tally chart of accounts as its own row (example rows shown in blue).
A39: 'Default Company Assignment' + the transaction's Flag together decide where an amount lands — see sheet 11.
A40: 'Split by Flag' means the ledger itself doesn't decide ownership; the transaction-level OLD/NEW/SHARED flag does.

Sheet 11 Transaction Master
A1: TRANSACTION MASTER
A2: Every voucher, one row. Flag drives every downstream schedule and statement.
A5: Date | B5: Voucher Number | C5: Voucher Type | D5: Ledger | E5: Party | F5: Narration | G5: Debit | H5: Credit | I5: Amount | J5: GST | K5: Project | L5: Customer | M5: Supplier | N5: Payment Mode | O5: Bank | P5: Cash | Q5: Old Project? | R5: New Project? | S5: Flag | T5: Adjustment Required? | U5: Recovered From Old? | V5: Suggested Flag (QA) | W5: Remarks | X5: Voucher Balanced?
A6: 2026-02-10 | B6: JV-0231 | C6: Purchase | D6: Site Material Purchase | E6: XYZ Timber Traders | F6: Plywood for Sandesh site | G6: 185000 | H6: 0 | I6: =IF(OR(G6<>"",H6<>""),G6-H6,"") -> 185000 | J6: 9250 | K6: Sandesh Residence | L6: Sandesh | N6: Bank | O6: HDFC Bank - New Co | Q6: =IFERROR(IF(K6="","N/A",IF(ISNUMBER(MATCH(K6,OLD_PROJECTS,0)),"Yes","No")),"N/A") -> No | R6: =IFERROR(IF(K6="","N/A",IF(Q6="Yes","No","Yes")),"N/A") -> Yes | S6: OLD | T6: =IFERROR(IF(S6="","",IF(S6="SHARED","Yes",IF(AND(INDEX(COA_OVERHEAD,MATCH(D6,COA_LEDGER,0))="Y",S6="OLD"),"Yes",IF(AND(INDEX(COA_CLASS,MATCH(D6,COA_LEDGER,0))="Income",S6="NEW",Q6="Yes"),"Yes","No")))),"Check Ledger") -> No | U6: Pending | V6: =IFERROR(IF(D6="","",IF(INDEX(COA_COMPANY,MATCH(D6,COA_LEDGER,0))="New Company","NEW",IF(INDEX(COA_COMPANY,MATCH(D6,COA_LEDGER,0))="Old Company","OLD",IF(Q6="Yes","OLD","NEW")))),"Check Ledger") -> NEW | W6: Recoverable from Old Co per Rule 5 | X6: =IFERROR(IF(B6="","",IF(ROUND(SUMIF(TXN_VNO,B6,TXN_DEBIT)-SUMIF(TXN_VNO,B6,TXN_CREDIT),2)=0,"Yes","No")),"") -> No
A7: 2026-02-15 | B7: JV-0245 | C7: Payment | D7: Office Rent | E7: Landlord - Kunnathpalam | F7: Feb rent - Al-Amana Tower | G7: 45000 | H7: 0 | I7: =IF(OR(G7<>"",H7<>""),G7-H7,"") -> 45000 | J7: 0 | N7: Bank | O7: HDFC Bank - New Co | Q7: =IFERROR(IF(K7="","N/A",IF(ISNUMBER(MATCH(K7,OLD_PROJECTS,0)),"Yes","No")),"N/A") -> N/A | R7: =IFERROR(IF(K7="","N/A",IF(Q7="Yes","No","Yes")),"N/A") -> N/A | S7: NEW | T7: =IFERROR(IF(S7="","",IF(S7="SHARED","Yes",IF(AND(INDEX(COA_OVERHEAD,MATCH(D7,COA_LEDGER,0))="Y",S7="OLD"),"Yes",IF(AND(INDEX(COA_CLASS,MATCH(D7,COA_LEDGER,0))="Income",S7="NEW",Q7="Yes"),"Yes","No")))),"Check Ledger") -> No | U7: N/A | V7: =IFERROR(IF(D7="","",IF(INDEX(COA_COMPANY,MATCH(D7,COA_LEDGER,0))="New Company","NEW",IF(INDEX(COA_COMPANY,MATCH(D7,COA_LEDGER,0))="Old Company","OLD",IF(Q7="Yes","OLD","NEW")))),"Check Ledger") -> NEW | W7: Rule 4 — overhead, New Co only | X7: =IFERROR(IF(B7="","",IF(ROUND(SUMIF(TXN_VNO,B7,TXN_DEBIT)-SUMIF(TXN_VNO,B7,TXN_CREDIT),2)=0,"Yes","No")),"") -> No
A8: 2026-03-01 | B8: SAL-0102 | C8: Sales | D8: Sales - Interior Projects | E8: Mr. Iqbal | F8: Progress billing - MC Enclave | G8: 0 | H8: 950000 | I8: =IF(OR(G8<>"",H8<>""),G8-H8,"") -> -950000 | J8: 171000 | K8: MC Enclave - Iqbal | L8: Mr. Iqbal | N8: Bank | O8: HDFC Bank - Old Co | Q8: =IFERROR(IF(K8="","N/A",IF(ISNUMBER(MATCH(K8,OLD_PROJECTS,0)),"Yes","No")),"N/A") -> No | R8: =IFERROR(IF(K8="","N/A",IF(Q8="Yes","No","Yes")),"N/A") -> Yes | S8: OLD | T8: =IFERROR(IF(S8="","",IF(S8="SHARED","Yes",IF(AND(INDEX(COA_OVERHEAD,MATCH(D8,COA_LEDGER,0))="Y",S8="OLD"),"Yes",IF(AND(INDEX(COA_CLASS,MATCH(D8,COA_LEDGER,0))="Income",S8="NEW",Q8="Yes"),"Yes","No")))),"Check Ledger") -> No | U8: N/A | V8: =IFERROR(IF(D8="","",IF(INDEX(COA_COMPANY,MATCH(D8,COA_LEDGER,0))="New Company","NEW",IF(INDEX(COA_COMPANY,MATCH(D8,COA_LEDGER,0))="Old Company","OLD",IF(Q8="Yes","OLD","NEW")))),"Check Ledger") -> OLD | W8: Rule 1 — revenue on ongoing project | X8: =IFERROR(IF(B8="","",IF(ROUND(SUMIF(TXN_VNO,B8,TXN_DEBIT)-SUMIF(TXN_VNO,B8,TXN_CREDIT),2)=0,"Yes","No")),"") -> No
I9: =IF(OR(G9<>"",H9<>""),G9-H9,"") | Q9: =IFERROR(IF(K9="","N/A",IF(ISNUMBER(MATCH(K9,OLD_PROJECTS,0)),"Yes","No")),"N/A") -> N/A | R9: =IFERROR(IF(K9="","N/A",IF(Q9="Yes","No","Yes")),"N/A") -> N/A | T9: =IFERROR(IF(S9="","",IF(S9="SHARED","Yes",IF(AND(INDEX(COA_OVERHEAD,MATCH(D9,COA_LEDGER,0))="Y",S9="OLD"),"Yes",IF(AND(INDEX(COA_CLASS,MATCH(D9,COA_LEDGER,0))="Income",S9="NEW",Q9="Yes"),"Yes","No")))),"Check Ledger") | V9: =IFERROR(IF(D9="","",IF(INDEX(COA_COMPANY,MATCH(D9,COA_LEDGER,0))="New Company","NEW",IF(INDEX(COA_COMPANY,MATCH(D9,COA_LEDGER,0))="Old Company","OLD",IF(Q9="Yes","OLD","NEW")))),"Check Ledger") | X9: =IFERROR(IF(B9="","",IF(ROUND(SUMIF(TXN_VNO,B9,TXN_DEBIT)-SUMIF(TXN_VNO,B9,TXN_CREDIT),2)=0,"Yes","No")),"")
I10: =IF(OR(G10<>"",H10<>""),G10-H10,"") | Q10: =IFERROR(IF(K10="","N/A",IF(ISNUMBER(MATCH(K10,OLD_PROJECTS,0)),"Yes","No")),"N/A") -> N/A | R10: =IFERROR(IF(K10="","N/A",IF(Q10="Yes","No","Yes")),"N/A") -> N/A | T10: =IFERROR(IF(S10="","",IF(S10="SHARED","Yes",IF(AND(INDEX(COA_OVERHEAD,MATCH(D10,COA_LEDGER,0))="Y",S10="OLD"),"Yes",IF(AND(INDEX(COA_CLASS,MATCH(D10,COA_LEDGER,0))="Income",S10="NEW",Q10="Yes"),"Yes","No")))),"Check Ledger") | V10: =IFERROR(IF(D10="","",IF(INDEX(COA_COMPANY,MATCH(D10,COA_LEDGER,0))="New Company","NEW",IF(INDEX(COA_COMPANY,MATCH(D10,COA_LEDGER,0))="Old Company","OLD",IF(Q10="Yes","OLD","NEW")))),"Check Ledger") | X10: =IFERROR(IF(B10="","",IF(ROUND(SUMIF(TXN_VNO,B10,TXN_DEBIT)-SUMIF(TXN_VNO,B10,TXN_CREDIT),2)=0,"Yes","No")),"")
I11: =IF(OR(G11<>"",H11<>""),G11-H11,"") | Q11: =IFERROR(IF(K11="","N/A",IF(ISNUMBER(MATCH(K11,OLD_PROJECTS,0)),"Yes","No")),"N/A") -> N/A | R11: =IFERROR(IF(K11="","N/A",IF(Q11="Yes","No","Yes")),"N/A") -> N/A | T11: =IFERROR(IF(S11="","",IF(S11="SHARED","Yes",IF(AND(INDEX(COA_OVERHEAD,MATCH(D11,COA_LEDGER,0))="Y",S11="OLD"),"Yes",IF(AND(INDEX(COA_CLASS,MATCH(D11,COA_LEDGER,0))="Income",S11="NEW",Q11="Yes"),"Yes","No")))),"Check Ledger") | V11: =IFERROR(IF(D11="","",IF(INDEX(COA_COMPANY,MATCH(D11,COA_LEDGER,0))="New Company","NEW",IF(INDEX(COA_COMPANY,MATCH(D11,COA_LEDGER,0))="Old Company","OLD",IF(Q11="Yes","OLD","NEW")))),"Check Ledger") | X11: =IFERROR(IF(B11="","",IF(ROUND(SUMIF(TXN_VNO,B11,TXN_DEBIT)-SUMIF(TXN_VNO,B11,TXN_CREDIT),2)=0,"Yes","No")),"")
I12: =IF(OR(G12<>"",H12<>""),G12-H12,"") | Q12: =IFERROR(IF(K12="","N/A",IF(ISNUMBER(MATCH(K12,OLD_PROJECTS,0)),"Yes","No")),"N/A") -> N/A | R12: =IFERROR(IF(K12="","N/A",IF(Q12="Yes","No","Yes")),"N/A") -> N/A | T12: =IFERROR(IF(S12="","",IF(S12="SHARED","Yes",IF(AND(INDEX(COA_OVERHEAD,MATCH(D12,COA_LEDGER,0))="Y",S12="OLD"),"Yes",IF(AND(INDEX(COA_CLASS,MATCH(D12,COA_LEDGER,0))="Income",S12="NEW",Q12="Yes"),"Yes","No")))),"Check Ledger") | V12: =IFERROR(IF(D12="","",IF(INDEX(COA_COMPANY,MATCH(D12,COA_LEDGER,0))="New Company","NEW",IF(INDEX(COA_COMPANY,MATCH(D12,COA_LEDGER,0))="Old Company","OLD",IF(Q12="Yes","OLD","NEW")))),"Check Ledger") | X12: =IFERROR(IF(B12="","",IF(ROUND(SUMIF(TXN_VNO,B12,TXN_DEBIT)-SUMIF(TXN_VNO,B12,TXN_CREDIT),2)=0,"Yes","No")),"")
I13: =IF(OR(G13<>"",H13<>""),G13-H13,"") | Q13: =IFERROR(IF(K13="","N/A",IF(ISNUMBER(MATCH(K13,OLD_PROJECTS,0)),"Yes","No")),"N/A") -> N/A | R13: =IFERROR(IF(K13="","N/A",IF(Q13="Yes","No","Yes")),"N/A") -> N/A | T13: =IFERROR(IF(S13="","",IF(S13="SHARED","Yes",IF(AND(INDEX(COA_OVERHEAD,MATCH(D13,COA_LEDGER,0))="Y",S13="OLD"),"Yes",IF(AND(INDEX(COA_CLASS,MATCH(D13,COA_LEDGER,0))="Income",S13="NEW",Q13="Yes"),"Yes","No")))),"Check Ledger") | V13: =IFERROR(IF(D13="","",IF(INDEX(COA_COMPANY,MATCH(D13,COA_LEDGER,0))="New Company","NEW",IF(INDEX(COA_COMPANY,MATCH(D13,COA_LEDGER,0))="Old Company","OLD",IF(Q13="Yes","OLD","NEW")))),"Check Ledger") | X13: =IFERROR(IF(B13="","",IF(ROUND(SUMIF(TXN_VNO,B13,TXN_DEBIT)-SUMIF(TXN_VNO,B13,TXN_CREDIT),2)=0,"Yes","No")),"")
I14: =IF(OR(G14<>"",H14<>""),G14-H14,"") | Q14: =IFERROR(IF(K14="","N/A",IF(ISNUMBER(MATCH(K14,OLD_PROJECTS,0)),"Yes","No")),"N/A") -> N/A | R14: =IFERROR(IF(K14="","N/A",IF(Q14="Yes","No","Yes")),"N/A") -> N/A | T14: =IFERROR(IF(S14="","",IF(S14="SHARED","Yes",IF(AND(INDEX(COA_OVERHEAD,MATCH(D14,COA_LEDGER,0))="Y",S14="OLD"),"Yes",IF(AND(INDEX(COA_CLASS,MATCH(D14,COA_LEDGER,0))="Income",S14="NEW",Q14="Yes"),"Yes","No")))),"Check Ledger") | V14: =IFERROR(IF(D14="","",IF(INDEX(COA_COMPANY,MATCH(D14,COA_LEDGER,0))="New Company","NEW",IF(INDEX(COA_COMPANY,MATCH(D14,COA_LEDGER,0))="Old Company","OLD",IF(Q14="Yes","OLD","NEW")))),"Check Ledger") | X14: =IFERROR(IF(B14="","",IF(ROUND(SUMIF(TXN_VNO,B14,TXN_DEBIT)-SUMIF(TXN_VNO,B14,TXN_CREDIT),2)=0,"Yes","No")),"")
I15: =IF(OR(G15<>"",H15<>""),G15-H15,"") | Q15: =IFERROR(IF(K15="","N/A",IF(ISNUMBER(MATCH(K15,OLD_PROJECTS,0)),"Yes","No")),"N/A") -> N/A | R15: =IFERROR(IF(K15="","N/A",IF(Q15="Yes","No","Yes")),"N/A") -> N/A | T15: =IFERROR(IF(S15="","",IF(S15="SHARED","Yes",IF(AND(INDEX(COA_OVERHEAD,MATCH(D15,COA_LEDGER,0))="Y",S15="OLD"),"Yes",IF(AND(INDEX(COA_CLASS,MATCH(D15,COA_LEDGER,0))="Income",S15="NEW",Q15="Yes"),"Yes","No")))),"Check Ledger") | V15: =IFERROR(IF(D15="","",IF(INDEX(COA_COMPANY,MATCH(D15,COA_LEDGER,0))="New Company","NEW",IF(INDEX(COA_COMPANY,MATCH(D15,COA_LEDGER,0))="Old Company","OLD",IF(Q15="Yes","OLD","NEW")))),"Check Ledger") | X15: =IFERROR(IF(B15="","",IF(ROUND(SUMIF(TXN_VNO,B15,TXN_DEBIT)-SUMIF(TXN_VNO,B15,TXN_CREDIT),2)=0,"Yes","No")),"")
I16: =IF(OR(G16<>"",H16<>""),G16-H16,"") | Q16: =IFERROR(IF(K16="","N/A",IF(ISNUMBER(MATCH(K16,OLD_PROJECTS,0)),"Yes","No")),"N/A") -> N/A | R16: =IFERROR(IF(K16="","N/A",IF(Q16="Yes","No","Yes")),"N/A") -> N/A | T16: =IFERROR(IF(S16="","",IF(S16="SHARED","Yes",IF(AND(INDEX(COA_OVERHEAD,MATCH(D16,COA_LEDGER,0))="Y",S16="OLD"),"Yes",IF(AND(INDEX(COA_CLASS,MATCH(D16,COA_LEDGER,0))="Income",S16="NEW",Q16="Yes"),"Yes","No")))),"Check Ledger") | V16: =IFERROR(IF(D16="","",IF(INDEX(COA_COMPANY,MATCH(D16,COA_LEDGER,0))="New Company","NEW",IF(INDEX(COA_COMPANY,MATCH(D16,COA_LEDGER,0))="Old Company","OLD",IF(Q16="Yes","OLD","NEW")))),"Check Ledger") | X16: =IFERROR(IF(B16="","",IF(ROUND(SUMIF(TXN_VNO,B16,TXN_DEBIT)-SUMIF(TXN_VNO,B16,TXN_CREDIT),2)=0,"Yes","No")),"")
I17: =IF(OR(G17<>"",H17<>""),G17-H17,"") | Q17: =IFERROR(IF(K17="","N/A",IF(ISNUMBER(MATCH(K17,OLD_PROJECTS,0)),"Yes","No")),"N/A") -> N/A | R17: =IFERROR(IF(K17="","N/A",IF(Q17="Yes","No","Yes")),"N/A") -> N/A | T17: =IFERROR(IF(S17="","",IF(S17="SHARED","Yes",IF(AND(INDEX(COA_OVERHEAD,MATCH(D17,COA_LEDGER,0))="Y",S17="OLD"),"Yes",IF(AND(INDEX(COA_CLASS,MATCH(D17,COA_LEDGER,0))="Income",S17="NEW",Q17="Yes"),"Yes","No")))),"Check Ledger") | V17: =IFERROR(IF(D17="","",IF(INDEX(COA_COMPANY,MATCH(D17,COA_LEDGER,0))="New Company","NEW",IF(INDEX(COA_COMPANY,MATCH(D17,COA_LEDGER,0))="Old Company","OLD",IF(Q17="Yes","OLD","NEW")))),"Check Ledger") | X17: =IFERROR(IF(B17="","",IF(ROUND(SUMIF(TXN_VNO,B17,TXN_DEBIT)-SUMIF(TXN_VNO,B17,TXN_CREDIT),2)=0,"Yes","No")),"")
I18: =IF(OR(G18<>"",H18<>""),G18-H18,"") | Q18: =IFERROR(IF(K18="","N/A",IF(ISNUMBER(MATCH(K18,OLD_PROJECTS,0)),"Yes","No")),"N/A") -> N/A | R18: =IFERROR(IF(K18="","N/A",IF(Q18="Yes","No","Yes")),"N/A") -> N/A | T18: =IFERROR(IF(S18="","",IF(S18="SHARED","Yes",IF(AND(INDEX(COA_OVERHEAD,MATCH(D18,COA_LEDGER,0))="Y",S18="OLD"),"Yes",IF(AND(INDEX(COA_CLASS,MATCH(D18,COA_LEDGER,0))="Income",S18="NEW",Q18="Yes"),"Yes","No")))),"Check Ledger") | V18: =IFERROR(IF(D18="","",IF(INDEX(COA_COMPANY,MATCH(D18,COA_LEDGER,0))="New Company","NEW",IF(INDEX(COA_COMPANY,MATCH(D18,COA_LEDGER,0))="Old Company","OLD",IF(Q18="Yes","OLD","NEW")))),"Check Ledger") | X18: =IFERROR(IF(B18="","",IF(ROUND(SUMIF(TXN_VNO,B18,TXN_DEBIT)-SUMIF(TXN_VNO,B18,TXN_CREDIT),2)=0,"Yes","No")),"")
I19: =IF(OR(G19<>"",H19<>""),G19-H19,"") | Q19: =IFERROR(IF(K19="","N/A",IF(ISNUMBER(MATCH(K19,OLD_PROJECTS,0)),"Yes","No")),"N/A") -> N/A | R19: =IFERROR(IF(K19="","N/A",IF(Q19="Yes","No","Yes")),"N/A") -> N/A | T19: =IFERROR(IF(S19="","",IF(S19="SHARED","Yes",IF(AND(INDEX(COA_OVERHEAD,MATCH(D19,COA_LEDGER,0))="Y",S19="OLD"),"Yes",IF(AND(INDEX(COA_CLASS,MATCH(D19,COA_LEDGER,0))="Income",S19="NEW",Q19="Yes"),"Yes","No")))),"Check Ledger") | V19: =IFERROR(IF(D19="","",IF(INDEX(COA_COMPANY,MATCH(D19,COA_LEDGER,0))="New Company","NEW",IF(INDEX(COA_COMPANY,MATCH(D19,COA_LEDGER,0))="Old Company","OLD",IF(Q19="Yes","OLD","NEW")))),"Check Ledger") | X19: =IFERROR(IF(B19="","",IF(ROUND(SUMIF(TXN_VNO,B19,TXN_DEBIT)-SUMIF(TXN_VNO,B19,TXN_CREDIT),2)=0,"Yes","No")),"")
I20: =IF(OR(G20<>"",H20<>""),G20-H20,"") | Q20: =IFERROR(IF(K20="","N/A",IF(ISNUMBER(MATCH(K20,OLD_PROJECTS,0)),"Yes","No")),"N/A") -> N/A | R20: =IFERROR(IF(K20="","N/A",IF(Q20="Yes","No","Yes")),"N/A") -> N/A | T20: =IFERROR(IF(S20="","",IF(S20="SHARED","Yes",IF(AND(INDEX(COA_OVERHEAD,MATCH(D20,COA_LEDGER,0))="Y",S20="OLD"),"Yes",IF(AND(INDEX(COA_CLASS,MATCH(D20,COA_LEDGER,0))="Income",S20="NEW",Q20="Yes"),"Yes","No")))),"Check Ledger") | V20: =IFERROR(IF(D20="","",IF(INDEX(COA_COMPANY,MATCH(D20,COA_LEDGER,0))="New Company","NEW",IF(INDEX(COA_COMPANY,MATCH(D20,COA_LEDGER,0))="Old Company","OLD",IF(Q20="Yes","OLD","NEW")))),"Check Ledger") | X20: =IFERROR(IF(B20="","",IF(ROUND(SUMIF(TXN_VNO,B20,TXN_DEBIT)-SUMIF(TXN_VNO,B20,TXN_CREDIT),2)=0,"Yes","No")),"")
... I505: =IF(OR(G505<>"",H505<>""),G505-H505,"") | Q505: =IFERROR(IF(K505="","N/A",IF(ISNUMBER(MATCH(K505,OLD_PROJECTS,0)),"Yes","No")),"N/A") -> N/A | R505: =IFERROR(IF(K505="","N/A",IF(Q505="Yes","No","Yes")),"N/A") -> N/A | T505: =IFERROR(IF(S505="","",IF(S505="SHARED","Yes",IF(AND(INDEX(COA_OVERHEAD,MATCH(D505,COA_LEDGER,0))="Y",S505="OLD"),"Yes",IF(AND(INDEX(COA_CLASS,MATCH(D505,COA_LEDGER,0))="Income",S505="NEW",Q505="Yes"),"Yes","No")))),"Check Ledger") | V505: =IFERROR(IF(D505="","",IF(INDEX(COA_COMPANY,MATCH(D505,COA_LEDGER,0))="New Company","NEW",IF(INDEX(COA_COMPANY,MATCH(D505,COA_LEDGER,0))="Old Company","OLD",IF(Q505="Yes","OLD","NEW")))),"Check Ledger") | X505: =IFERROR(IF(B505="","",IF(ROUND(SUMIF(TXN_VNO,B505,TXN_DEBIT)-SUMIF(TXN_VNO,B505,TXN_CREDIT),2)=0,"Yes","No")),"")
A511: HOW TO USE THIS SHEET
A512: Paste/enter one row per voucher (columns A-N, P, S, U, W are your inputs — shown in blue for the 3 example rows).
A513: Columns I, Q, R, T, V (Amount, Old Project?, New Project?, Adjustment Required?, Suggested Flag) are FORMULAS — do not overtype them.
A514: 'Flag' (col S) is your OLD/NEW/SHARED classification per voucher. 'Suggested Flag' (col V) is the system's own recommendation from the Chart of Accounts + project match — a mismatch is highlighted amber for review, but is NEVER auto-applied.
A515: 'Adjustment Required?' turns Yes (highlighted red) when a voucher looks like it breaks Rule 1 or Rule 4, or is flagged SHARED — review these in sheet 26 (Adjustment Journals).
A516: 'Recovered From Old?' is entered manually as costs are actually invoiced to Old Co — reconciled against sheet 22 (Project Cost Recovery).
A517: The table is sized for 100,000+ rows; formulas are pre-filled for the first 500 rows for file size — select row 505's formula cells and fill down as far as you add data.
A518: IMPORTANT: a real Tally voucher normally posts to 2+ ledgers (e.g. Dr Site Material Purchase / Cr Bank). Paste EVERY ledger leg as its own row under the SAME Voucher Number — the Trial Balance and 'Voucher Balanced?' check only reconcile to zero once both legs of each voucher are present. The 3 example rows above are illustrative single legs only, to show column usage — they will not balance on their own.

Sheet 12 Intercompany Ledger
A1: INTERCOMPANY LEDGER
A2: Auto-generated from Transaction Master. Tracks what New Co is owed for executing Old Co's projects at cost (Rule 3/5).
A5: Component | B5: Amount
A6: Direct project cost incurred BY New Co bank/cash FOR Old Co projects | B6: =SUMIFS(TXN_DEBIT,TXN_FLAG,"OLD",TXN_OLDPROJ,"Yes",TXN_BANK,"*New Co*")+SUMIFS(TXN_DEBIT,TXN_FLAG,"OLD",TXN_OLDPROJ,"Yes",TXN_CASH,"*New Co*") -> 0
A7: Less: Amount already recovered/reimbursed from Old Co | B7: =SUMIFS(TXN_DEBIT,TXN_RECOV,"Yes",TXN_OLDPROJ,"Yes") -> 0
A8: NET INTERCOMPANY RECEIVABLE — New Co from Old Co | B8: =B6-B7 -> 0
A11: This account must appear as:
A12: • An ASSET (Amount Due from New Co) in the Old Company Balance Sheet, OR a payable if negative
A13: • An ASSET (Amount Due from Old Co) in the New Company Balance Sheet — mirrors sheet 17/18 automatically
A16: HOW TO USE THIS SHEET
A17: This sheet nets the direct cost New Co has funded on Old Co's behalf against what's already been recovered.
A18: It reads live from Transaction Master (sheet 11) — nothing here is hardcoded.
A19: The Bank/Cash text match ('*New Co*') assumes bank ledger names contain 'New Co' — rename to match your actual bank ledger naming in sheet 10 if different.

Sheet 13 Old Company TB
A1: TRIAL BALANCE — OLD COMPANY (Appletree Interiors)
A2: Auto-summed from Transaction Master where Flag = OLD. SHARED items excluded pending sheet 26 adjustment.
A5: Ledger | B5: Group | C5: Classification | D5: Debit | E5: Credit
A6: ='10 Chart of Accounts'!A5 -> Sales - Interior Projects | B6: ='10 Chart of Accounts'!B5 -> Sales Accounts | C6: ='10 Chart of Accounts'!D5 -> Income | D6: =SUMIFS(TXN_DEBIT,TXN_LEDGER,A6,TXN_FLAG,"OLD") -> 0 | E6: =SUMIFS(TXN_CREDIT,TXN_LEDGER,A6,TXN_FLAG,"OLD") -> 950000
A7: ='10 Chart of Accounts'!A6 -> Site Material Purchase | B7: ='10 Chart of Accounts'!B6 -> Purchase Accounts | C7: ='10 Chart of Accounts'!D6 -> Direct Cost | D7: =SUMIFS(TXN_DEBIT,TXN_LEDGER,A7,TXN_FLAG,"OLD") -> 185000 | E7: =SUMIFS(TXN_CREDIT,TXN_LEDGER,A7,TXN_FLAG,"OLD") -> 0
A8: ='10 Chart of Accounts'!A7 -> Site Labour Charges | B8: ='10 Chart of Accounts'!B7 -> Direct Expenses | C8: ='10 Chart of Accounts'!D7 -> Direct Cost | D8: =SUMIFS(TXN_DEBIT,TXN_LEDGER,A8,TXN_FLAG,"OLD") -> 0 | E8: =SUMIFS(TXN_CREDIT,TXN_LEDGER,A8,TXN_FLAG,"OLD") -> 0
A9: ='10 Chart of Accounts'!A8 -> Subcontract Charges | B9: ='10 Chart of Accounts'!B8 -> Direct Expenses | C9: ='10 Chart of Accounts'!D8 -> Direct Cost | D9: =SUMIFS(TXN_DEBIT,TXN_LEDGER,A9,TXN_FLAG,"OLD") -> 0 | E9: =SUMIFS(TXN_CREDIT,TXN_LEDGER,A9,TXN_FLAG,"OLD") -> 0
A10: ='10 Chart of Accounts'!A9 -> Site Transport | B10: ='10 Chart of Accounts'!B9 -> Direct Expenses | C10: ='10 Chart of Accounts'!D9 -> Direct Cost | D10: =SUMIFS(TXN_DEBIT,TXN_LEDGER,A10,TXN_FLAG,"OLD") -> 0 | E10: =SUMIFS(TXN_CREDIT,TXN_LEDGER,A10,TXN_FLAG,"OLD") -> 0
A11: ='10 Chart of Accounts'!A10 -> Office Rent | B11: ='10 Chart of Accounts'!B10 -> Indirect Expenses | C11: ='10 Chart of Accounts'!D10 -> Indirect Cost | D11: =SUMIFS(TXN_DEBIT,TXN_LEDGER,A11,TXN_FLAG,"OLD") -> 0 | E11: =SUMIFS(TXN_CREDIT,TXN_LEDGER,A11,TXN_FLAG,"OLD") -> 0
A12: ='10 Chart of Accounts'!A11 -> Office Salary | B12: ='10 Chart of Accounts'!B11 -> Indirect Expenses | C12: ='10 Chart of Accounts'!D11 -> Indirect Cost | D12: =SUMIFS(TXN_DEBIT,TXN_LEDGER,A12,TXN_FLAG,"OLD") -> 0 | E12: =SUMIFS(TXN_CREDIT,TXN_LEDGER,A12,TXN_FLAG,"OLD") -> 0
A13: ='10 Chart of Accounts'!A12 -> Admin Salary | B13: ='10 Chart of Accounts'!B12 -> Indirect Expenses | C13: ='10 Chart of Accounts'!D12 -> Indirect Cost | D13: =SUMIFS(TXN_DEBIT,TXN_LEDGER,A13,TXN_FLAG,"OLD") -> 0 | E13: =SUMIFS(TXN_CREDIT,TXN_LEDGER,A13,TXN_FLAG,"OLD") -> 0
A14: ='10 Chart of Accounts'!A13 -> Electricity Charges | B14: ='10 Chart of Accounts'!B13 -> Indirect Expenses | C14: ='10 Chart of Accounts'!D13 -> Indirect Cost | D14: =SUMIFS(TXN_DEBIT,TXN_LEDGER,A14,TXN_FLAG,"OLD") -> 0 | E14: =SUMIFS(TXN_CREDIT,TXN_LEDGER,A14,TXN_FLAG,"OLD") -> 0
A15: ='10 Chart of Accounts'!A14 -> Internet & Telephone | B15: ='10 Chart of Accounts'!B14 -> Indirect Expenses | C15: ='10 Chart of Accounts'!D14 -> Indirect Cost | D15: =SUMIFS(TXN_DEBIT,TXN_LEDGER,A15,TXN_FLAG,"OLD") -> 0 | E15: =SUMIFS(TXN_CREDIT,TXN_LEDGER,A15,TXN_FLAG,"OLD") -> 0
A16: ='10 Chart of Accounts'!A15 -> Fuel Expenses | B16: ='10 Chart of Accounts'!B15 -> Indirect Expenses | C16: ='10 Chart of Accounts'!D15 -> Indirect Cost | D16: =SUMIFS(TXN_DEBIT,TXN_LEDGER,A16,TXN_FLAG,"OLD") -> 0 | E16: =SUMIFS(TXN_CREDIT,TXN_LEDGER,A16,TXN_FLAG,"OLD") -> 0
A17: ='10 Chart of Accounts'!A16 -> Marketing Expenses | B17: ='10 Chart of Accounts'!B16 -> Indirect Expenses | C17: ='10 Chart of Accounts'!D16 -> Indirect Cost | D17: =SUMIFS(TXN_DEBIT,TXN_LEDGER,A17,TXN_FLAG,"OLD") -> 0 | E17: =SUMIFS(TXN_CREDIT,TXN_LEDGER,A17,TXN_FLAG,"OLD") -> 0
... A35: ='10 Chart of Accounts'!A34 -> Intercompany - New Co A/c | B35: ='10 Chart of Accounts'!B34 -> Intercompany | C35: ='10 Chart of Accounts'!D34 -> Intercompany | D35: =SUMIFS(TXN_DEBIT,TXN_LEDGER,A35,TXN_FLAG,"OLD") -> 0 | E35: =SUMIFS(TXN_CREDIT,TXN_LEDGER,A35,TXN_FLAG,"OLD") -> 0
A37: TOTAL | D37: =SUM(D6:D35) -> 185000 | E37: =SUM(E6:E35) -> 950000
A38: Difference (must be 0) | D38: =D37-E37 -> -765000

Sheet 14 New Company TB
A1: TRIAL BALANCE — NEW COMPANY (Appletree Interiors Pvt Ltd)
A2: Auto-summed from Transaction Master where Flag = NEW. SHARED items excluded pending sheet 26 adjustment.
A5: Ledger | B5: Group | C5: Classification | D5: Debit | E5: Credit
A6: ='10 Chart of Accounts'!A5 -> Sales - Interior Projects | B6: ='10 Chart of Accounts'!B5 -> Sales Accounts | C6: ='10 Chart of Accounts'!D5 -> Income | D6: =SUMIFS(TXN_DEBIT,TXN_LEDGER,A6,TXN_FLAG,"NEW") -> 0 | E6: =SUMIFS(TXN_CREDIT,TXN_LEDGER,A6,TXN_FLAG,"NEW") -> 0
A7: ='10 Chart of Accounts'!A6 -> Site Material Purchase | B7: ='10 Chart of Accounts'!B6 -> Purchase Accounts | C7: ='10 Chart of Accounts'!D6 -> Direct Cost | D7: =SUMIFS(TXN_DEBIT,TXN_LEDGER,A7,TXN_FLAG,"NEW") -> 0 | E7: =SUMIFS(TXN_CREDIT,TXN_LEDGER,A7,TXN_FLAG,"NEW") -> 0
A8: ='10 Chart of Accounts'!A7 -> Site Labour Charges | B8: ='10 Chart of Accounts'!B7 -> Direct Expenses | C8: ='10 Chart of Accounts'!D7 -> Direct Cost | D8: =SUMIFS(TXN_DEBIT,TXN_LEDGER,A8,TXN_FLAG,"NEW") -> 0 | E8: =SUMIFS(TXN_CREDIT,TXN_LEDGER,A8,TXN_FLAG,"NEW") -> 0
A9: ='10 Chart of Accounts'!A8 -> Subcontract Charges | B9: ='10 Chart of Accounts'!B8 -> Direct Expenses | C9: ='10 Chart of Accounts'!D8 -> Direct Cost | D9: =SUMIFS(TXN_DEBIT,TXN_LEDGER,A9,TXN_FLAG,"NEW") -> 0 | E9: =SUMIFS(TXN_CREDIT,TXN_LEDGER,A9,TXN_FLAG,"NEW") -> 0
A10: ='10 Chart of Accounts'!A9 -> Site Transport | B10: ='10 Chart of Accounts'!B9 -> Direct Expenses | C10: ='10 Chart of Accounts'!D9 -> Direct Cost | D10: =SUMIFS(TXN_DEBIT,TXN_LEDGER,A10,TXN_FLAG,"NEW") -> 0 | E10: =SUMIFS(TXN_CREDIT,TXN_LEDGER,A10,TXN_FLAG,"NEW") -> 0
A11: ='10 Chart of Accounts'!A10 -> Office Rent | B11: ='10 Chart of Accounts'!B10 -> Indirect Expenses | C11: ='10 Chart of Accounts'!D10 -> Indirect Cost | D11: =SUMIFS(TXN_DEBIT,TXN_LEDGER,A11,TXN_FLAG,"NEW") -> 45000 | E11: =SUMIFS(TXN_CREDIT,TXN_LEDGER,A11,TXN_FLAG,"NEW") -> 0
A12: ='10 Chart of Accounts'!A11 -> Office Salary | B12: ='10 Chart of Accounts'!B11 -> Indirect Expenses | C12: ='10 Chart of Accounts'!D11 -> Indirect Cost | D12: =SUMIFS(TXN_DEBIT,TXN_LEDGER,A12,TXN_FLAG,"NEW") -> 0 | E12: =SUMIFS(TXN_CREDIT,TXN_LEDGER,A12,TXN_FLAG,"NEW") -> 0
A13: ='10 Chart of Accounts'!A12 -> Admin Salary | B13: ='10 Chart of Accounts'!B12 -> Indirect Expenses | C13: ='10 Chart of Accounts'!D12 -> Indirect Cost | D13: =SUMIFS(TXN_DEBIT,TXN_LEDGER,A13,TXN_FLAG,"NEW") -> 0 | E13: =SUMIFS(TXN_CREDIT,TXN_LEDGER,A13,TXN_FLAG,"NEW") -> 0
A14: ='10 Chart of Accounts'!A13 -> Electricity Charges | B14: ='10 Chart of Accounts'!B13 -> Indirect Expenses | C14: ='10 Chart of Accounts'!D13 -> Indirect Cost | D14: =SUMIFS(TXN_DEBIT,TXN_LEDGER,A14,TXN_FLAG,"NEW") -> 0 | E14: =SUMIFS(TXN_CREDIT,TXN_LEDGER,A14,TXN_FLAG,"NEW") -> 0
A15: ='10 Chart of Accounts'!A14 -> Internet & Telephone | B15: ='10 Chart of Accounts'!B14 -> Indirect Expenses | C15: ='10 Chart of Accounts'!D14 -> Indirect Cost | D15: =SUMIFS(TXN_DEBIT,TXN_LEDGER,A15,TXN_FLAG,"NEW") -> 0 | E15: =SUMIFS(TXN_CREDIT,TXN_LEDGER,A15,TXN_FLAG,"NEW") -> 0
A16: ='10 Chart of Accounts'!A15 -> Fuel Expenses | B16: ='10 Chart of Accounts'!B15 -> Indirect Expenses | C16: ='10 Chart of Accounts'!D15 -> Indirect Cost | D16: =SUMIFS(TXN_DEBIT,TXN_LEDGER,A16,TXN_FLAG,"NEW") -> 0 | E16: =SUMIFS(TXN_CREDIT,TXN_LEDGER,A16,TXN_FLAG,"NEW") -> 0
A17: ='10 Chart of Accounts'!A16 -> Marketing Expenses | B17: ='10 Chart of Accounts'!B16 -> Indirect Expenses | C17: ='10 Chart of Accounts'!D16 -> Indirect Cost | D17: =SUMIFS(TXN_DEBIT,TXN_LEDGER,A17,TXN_FLAG,"NEW") -> 0 | E17: =SUMIFS(TXN_CREDIT,TXN_LEDGER,A17,TXN_FLAG,"NEW") -> 0
... A35: ='10 Chart of Accounts'!A34 -> Intercompany - New Co A/c | B35: ='10 Chart of Accounts'!B34 -> Intercompany | C35: ='10 Chart of Accounts'!D34 -> Intercompany | D35: =SUMIFS(TXN_DEBIT,TXN_LEDGER,A35,TXN_FLAG,"NEW") -> 0 | E35: =SUMIFS(TXN_CREDIT,TXN_LEDGER,A35,TXN_FLAG,"NEW") -> 0
A37: TOTAL | D37: =SUM(D6:D35) -> 45000 | E37: =SUM(E6:E35) -> 0
A38: Difference (must be 0) | D38: =D37-E37 -> 45000

Sheet 15 Old Company P&L
A1: PROFIT & LOSS — OLD COMPANY
A2: Income and Expense ledgers only, Flag = OLD.
A5: INCOME
A6: Sales - Interior Projects | B6: =SUMIFS(TXN_CREDIT,TXN_LEDGER,"Sales - Interior Projects",TXN_FLAG,"OLD")-SUMIFS(TXN_DEBIT,TXN_LEDGER,"Sales - Interior Projects",TXN_FLAG,"OLD") -> 950000
A7: Total Income | B7: =SUM(B6:B6) -> 950000
A9: EXPENSES (Direct + Indirect)
A10: Site Material Purchase | B10: =SUMIFS(TXN_DEBIT,TXN_LEDGER,"Site Material Purchase",TXN_FLAG,"OLD")-SUMIFS(TXN_CREDIT,TXN_LEDGER,"Site Material Purchase",TXN_FLAG,"OLD") -> 185000
A11: Site Labour Charges | B11: =SUMIFS(TXN_DEBIT,TXN_LEDGER,"Site Labour Charges",TXN_FLAG,"OLD")-SUMIFS(TXN_CREDIT,TXN_LEDGER,"Site Labour Charges",TXN_FLAG,"OLD") -> 0
A12: Subcontract Charges | B12: =SUMIFS(TXN_DEBIT,TXN_LEDGER,"Subcontract Charges",TXN_FLAG,"OLD")-SUMIFS(TXN_CREDIT,TXN_LEDGER,"Subcontract Charges",TXN_FLAG,"OLD") -> 0
A13: Site Transport | B13: =SUMIFS(TXN_DEBIT,TXN_LEDGER,"Site Transport",TXN_FLAG,"OLD")-SUMIFS(TXN_CREDIT,TXN_LEDGER,"Site Transport",TXN_FLAG,"OLD") -> 0
A14: Office Rent | B14: =SUMIFS(TXN_DEBIT,TXN_LEDGER,"Office Rent",TXN_FLAG,"OLD")-SUMIFS(TXN_CREDIT,TXN_LEDGER,"Office Rent",TXN_FLAG,"OLD") -> 0
A15: Office Salary | B15: =SUMIFS(TXN_DEBIT,TXN_LEDGER,"Office Salary",TXN_FLAG,"OLD")-SUMIFS(TXN_CREDIT,TXN_LEDGER,"Office Salary",TXN_FLAG,"OLD") -> 0
A16: Admin Salary | B16: =SUMIFS(TXN_DEBIT,TXN_LEDGER,"Admin Salary",TXN_FLAG,"OLD")-SUMIFS(TXN_CREDIT,TXN_LEDGER,"Admin Salary",TXN_FLAG,"OLD") -> 0
A17: Electricity Charges | B17: =SUMIFS(TXN_DEBIT,TXN_LEDGER,"Electricity Charges",TXN_FLAG,"OLD")-SUMIFS(TXN_CREDIT,TXN_LEDGER,"Electricity Charges",TXN_FLAG,"OLD") -> 0
A18: Internet & Telephone | B18: =SUMIFS(TXN_DEBIT,TXN_LEDGER,"Internet & Telephone",TXN_FLAG,"OLD")-SUMIFS(TXN_CREDIT,TXN_LEDGER,"Internet & Telephone",TXN_FLAG,"OLD") -> 0
A19: Fuel Expenses | B19: =SUMIFS(TXN_DEBIT,TXN_LEDGER,"Fuel Expenses",TXN_FLAG,"OLD")-SUMIFS(TXN_CREDIT,TXN_LEDGER,"Fuel Expenses",TXN_FLAG,"OLD") -> 0
A20: Marketing Expenses | B20: =SUMIFS(TXN_DEBIT,TXN_LEDGER,"Marketing Expenses",TXN_FLAG,"OLD")-SUMIFS(TXN_CREDIT,TXN_LEDGER,"Marketing Expenses",TXN_FLAG,"OLD") -> 0
A21: Professional & Audit Fees | B21: =SUMIFS(TXN_DEBIT,TXN_LEDGER,"Professional & Audit Fees",TXN_FLAG,"OLD")-SUMIFS(TXN_CREDIT,TXN_LEDGER,"Professional & Audit Fees",TXN_FLAG,"OLD") -> 0
A22: Vehicle Running Expenses | B22: =SUMIFS(TXN_DEBIT,TXN_LEDGER,"Vehicle Running Expenses",TXN_FLAG,"OLD")-SUMIFS(TXN_CREDIT,TXN_LEDGER,"Vehicle Running Expenses",TXN_FLAG,"OLD") -> 0
A23: Software & Subscriptions | B23: =SUMIFS(TXN_DEBIT,TXN_LEDGER,"Software & Subscriptions",TXN_FLAG,"OLD")-SUMIFS(TXN_CREDIT,TXN_LEDGER,"Software & Subscriptions",TXN_FLAG,"OLD") -> 0
A24: Printing & Stationery | B24: =SUMIFS(TXN_DEBIT,TXN_LEDGER,"Printing & Stationery",TXN_FLAG,"OLD")-SUMIFS(TXN_CREDIT,TXN_LEDGER,"Printing & Stationery",TXN_FLAG,"OLD") -> 0
A25: Factory Overhead | B25: =SUMIFS(TXN_DEBIT,TXN_LEDGER,"Factory Overhead",TXN_FLAG,"OLD")-SUMIFS(TXN_CREDIT,TXN_LEDGER,"Factory Overhead",TXN_FLAG,"OLD") -> 0
A26: Total Expenses | B26: =SUM(B10:B25) -> 185000
A28: NET PROFIT / (LOSS) | B28: =B7-B26 -> 765000

Sheet 16 New Company P&L
A1: PROFIT & LOSS — NEW COMPANY
A2: Income and Expense ledgers only, Flag = NEW.
A5: INCOME
A6: Sales - Interior Projects | B6: =SUMIFS(TXN_CREDIT,TXN_LEDGER,"Sales - Interior Projects",TXN_FLAG,"NEW")-SUMIFS(TXN_DEBIT,TXN_LEDGER,"Sales - Interior Projects",TXN_FLAG,"NEW") -> 0
A7: Total Income | B7: =SUM(B6:B6) -> 0
A9: EXPENSES (Direct + Indirect)
A10: Site Material Purchase | B10: =SUMIFS(TXN_DEBIT,TXN_LEDGER,"Site Material Purchase",TXN_FLAG,"NEW")-SUMIFS(TXN_CREDIT,TXN_LEDGER,"Site Material Purchase",TXN_FLAG,"NEW") -> 0
A11: Site Labour Charges | B11: =SUMIFS(TXN_DEBIT,TXN_LEDGER,"Site Labour Charges",TXN_FLAG,"NEW")-SUMIFS(TXN_CREDIT,TXN_LEDGER,"Site Labour Charges",TXN_FLAG,"NEW") -> 0
A12: Subcontract Charges | B12: =SUMIFS(TXN_DEBIT,TXN_LEDGER,"Subcontract Charges",TXN_FLAG,"NEW")-SUMIFS(TXN_CREDIT,TXN_LEDGER,"Subcontract Charges",TXN_FLAG,"NEW") -> 0
A13: Site Transport | B13: =SUMIFS(TXN_DEBIT,TXN_LEDGER,"Site Transport",TXN_FLAG,"NEW")-SUMIFS(TXN_CREDIT,TXN_LEDGER,"Site Transport",TXN_FLAG,"NEW") -> 0
A14: Office Rent | B14: =SUMIFS(TXN_DEBIT,TXN_LEDGER,"Office Rent",TXN_FLAG,"NEW")-SUMIFS(TXN_CREDIT,TXN_LEDGER,"Office Rent",TXN_FLAG,"NEW") -> 45000
A15: Office Salary | B15: =SUMIFS(TXN_DEBIT,TXN_LEDGER,"Office Salary",TXN_FLAG,"NEW")-SUMIFS(TXN_CREDIT,TXN_LEDGER,"Office Salary",TXN_FLAG,"NEW") -> 0
A16: Admin Salary | B16: =SUMIFS(TXN_DEBIT,TXN_LEDGER,"Admin Salary",TXN_FLAG,"NEW")-SUMIFS(TXN_CREDIT,TXN_LEDGER,"Admin Salary",TXN_FLAG,"NEW") -> 0
A17: Electricity Charges | B17: =SUMIFS(TXN_DEBIT,TXN_LEDGER,"Electricity Charges",TXN_FLAG,"NEW")-SUMIFS(TXN_CREDIT,TXN_LEDGER,"Electricity Charges",TXN_FLAG,"NEW") -> 0
A18: Internet & Telephone | B18: =SUMIFS(TXN_DEBIT,TXN_LEDGER,"Internet & Telephone",TXN_FLAG,"NEW")-SUMIFS(TXN_CREDIT,TXN_LEDGER,"Internet & Telephone",TXN_FLAG,"NEW") -> 0
A19: Fuel Expenses | B19: =SUMIFS(TXN_DEBIT,TXN_LEDGER,"Fuel Expenses",TXN_FLAG,"NEW")-SUMIFS(TXN_CREDIT,TXN_LEDGER,"Fuel Expenses",TXN_FLAG,"NEW") -> 0
A20: Marketing Expenses | B20: =SUMIFS(TXN_DEBIT,TXN_LEDGER,"Marketing Expenses",TXN_FLAG,"NEW")-SUMIFS(TXN_CREDIT,TXN_LEDGER,"Marketing Expenses",TXN_FLAG,"NEW") -> 0
A21: Professional & Audit Fees | B21: =SUMIFS(TXN_DEBIT,TXN_LEDGER,"Professional & Audit Fees",TXN_FLAG,"NEW")-SUMIFS(TXN_CREDIT,TXN_LEDGER,"Professional & Audit Fees",TXN_FLAG,"NEW") -> 0
A22: Vehicle Running Expenses | B22: =SUMIFS(TXN_DEBIT,TXN_LEDGER,"Vehicle Running Expenses",TXN_FLAG,"NEW")-SUMIFS(TXN_CREDIT,TXN_LEDGER,"Vehicle Running Expenses",TXN_FLAG,"NEW") -> 0
A23: Software & Subscriptions | B23: =SUMIFS(TXN_DEBIT,TXN_LEDGER,"Software & Subscriptions",TXN_FLAG,"NEW")-SUMIFS(TXN_CREDIT,TXN_LEDGER,"Software & Subscriptions",TXN_FLAG,"NEW") -> 0
A24: Printing & Stationery | B24: =SUMIFS(TXN_DEBIT,TXN_LEDGER,"Printing & Stationery",TXN_FLAG,"NEW")-SUMIFS(TXN_CREDIT,TXN_LEDGER,"Printing & Stationery",TXN_FLAG,"NEW") -> 0
A25: Factory Overhead | B25: =SUMIFS(TXN_DEBIT,TXN_LEDGER,"Factory Overhead",TXN_FLAG,"NEW")-SUMIFS(TXN_CREDIT,TXN_LEDGER,"Factory Overhead",TXN_FLAG,"NEW") -> 0
A26: Total Expenses | B26: =SUM(B10:B25) -> 45000
A28: NET PROFIT / (LOSS) | B28: =B7-B26 -> -45000

Sheet 17 Old Company Balance Sheet
A1: BALANCE SHEET — OLD COMPANY
A2: Asset/Liability/Bank/Cash/Stock/GST/Loan/Capital ledgers, Flag = OLD.
A5: ASSETS
A6: Sundry Debtors | B6: =SUMIFS(TXN_DEBIT,TXN_LEDGER,"Sundry Debtors",TXN_FLAG,"OLD")-SUMIFS(TXN_CREDIT,TXN_LEDGER,"Sundry Debtors",TXN_FLAG,"OLD") -> 0
A7: HDFC Bank - Old Co | B7: =SUMIFS(TXN_DEBIT,TXN_LEDGER,"HDFC Bank - Old Co",TXN_FLAG,"OLD")-SUMIFS(TXN_CREDIT,TXN_LEDGER,"HDFC Bank - Old Co",TXN_FLAG,"OLD") -> 0
A8: HDFC Bank - New Co | B8: =SUMIFS(TXN_DEBIT,TXN_LEDGER,"HDFC Bank - New Co",TXN_FLAG,"OLD")-SUMIFS(TXN_CREDIT,TXN_LEDGER,"HDFC Bank - New Co",TXN_FLAG,"OLD") -> 0
A9: Cash | B9: =SUMIFS(TXN_DEBIT,TXN_LEDGER,"Cash",TXN_FLAG,"OLD")-SUMIFS(TXN_CREDIT,TXN_LEDGER,"Cash",TXN_FLAG,"OLD") -> 0
A10: Raw Material Stock | B10: =SUMIFS(TXN_DEBIT,TXN_LEDGER,"Raw Material Stock",TXN_FLAG,"OLD")-SUMIFS(TXN_CREDIT,TXN_LEDGER,"Raw Material Stock",TXN_FLAG,"OLD") -> 0
A11: Intercompany Balance (from sheet 12) | B11: ='12 Intercompany Ledger'!B8 -> 0
A12: Total Assets | B12: =SUM(B6:B11) -> 0
A14: LIABILITIES & CAPITAL
A15: Sundry Creditors | B15: =SUMIFS(TXN_CREDIT,TXN_LEDGER,"Sundry Creditors",TXN_FLAG,"OLD")-SUMIFS(TXN_DEBIT,TXN_LEDGER,"Sundry Creditors",TXN_FLAG,"OLD") -> 0
A16: Customer Advance | B16: =SUMIFS(TXN_CREDIT,TXN_LEDGER,"Customer Advance",TXN_FLAG,"OLD")-SUMIFS(TXN_DEBIT,TXN_LEDGER,"Customer Advance",TXN_FLAG,"OLD") -> 0
A17: Bank Loan | B17: =SUMIFS(TXN_CREDIT,TXN_LEDGER,"Bank Loan",TXN_FLAG,"OLD")-SUMIFS(TXN_DEBIT,TXN_LEDGER,"Bank Loan",TXN_FLAG,"OLD") -> 0
A18: Capital Account | B18: =SUMIFS(TXN_CREDIT,TXN_LEDGER,"Capital Account",TXN_FLAG,"OLD")-SUMIFS(TXN_DEBIT,TXN_LEDGER,"Capital Account",TXN_FLAG,"OLD") -> 0
A19: Intercompany Balance (from sheet 12) | B19: =0 -> 0
A20: Total Liabilities & Capital | B20: =SUM(B15:B19) -> 0
A22: Add: Current Period Profit/(Loss) (link to P&L sheet's Net Profit cell) | B22: 0
A24: CHECK: Total Assets − (Total Liabilities & Capital) — must be 0 | B24: =B12-B20 -> 0

Sheet 18 New Company Balance Sheet
A1: BALANCE SHEET — NEW COMPANY
A2: Asset/Liability/Bank/Cash/Stock/GST/Loan/Capital ledgers, Flag = NEW.
A5: ASSETS
A6: Sundry Debtors | B6: =SUMIFS(TXN_DEBIT,TXN_LEDGER,"Sundry Debtors",TXN_FLAG,"NEW")-SUMIFS(TXN_CREDIT,TXN_LEDGER,"Sundry Debtors",TXN_FLAG,"NEW") -> 0
A7: HDFC Bank - Old Co | B7: =SUMIFS(TXN_DEBIT,TXN_LEDGER,"HDFC Bank - Old Co",TXN_FLAG,"NEW")-SUMIFS(TXN_CREDIT,TXN_LEDGER,"HDFC Bank - Old Co",TXN_FLAG,"NEW") -> 0
A8: HDFC Bank - New Co | B8: =SUMIFS(TXN_DEBIT,TXN_LEDGER,"HDFC Bank - New Co",TXN_FLAG,"NEW")-SUMIFS(TXN_CREDIT,TXN_LEDGER,"HDFC Bank - New Co",TXN_FLAG,"NEW") -> 0
A9: Cash | B9: =SUMIFS(TXN_DEBIT,TXN_LEDGER,"Cash",TXN_FLAG,"NEW")-SUMIFS(TXN_CREDIT,TXN_LEDGER,"Cash",TXN_FLAG,"NEW") -> 0
A10: Raw Material Stock | B10: =SUMIFS(TXN_DEBIT,TXN_LEDGER,"Raw Material Stock",TXN_FLAG,"NEW")-SUMIFS(TXN_CREDIT,TXN_LEDGER,"Raw Material Stock",TXN_FLAG,"NEW") -> 0
A11: Intercompany Balance (from sheet 12) | B11: ='12 Intercompany Ledger'!B8 -> 0
A12: Total Assets | B12: =SUM(B6:B11) -> 0
A14: LIABILITIES & CAPITAL
A15: Sundry Creditors | B15: =SUMIFS(TXN_CREDIT,TXN_LEDGER,"Sundry Creditors",TXN_FLAG,"NEW")-SUMIFS(TXN_DEBIT,TXN_LEDGER,"Sundry Creditors",TXN_FLAG,"NEW") -> 0
A16: Customer Advance | B16: =SUMIFS(TXN_CREDIT,TXN_LEDGER,"Customer Advance",TXN_FLAG,"NEW")-SUMIFS(TXN_DEBIT,TXN_LEDGER,"Customer Advance",TXN_FLAG,"NEW") -> 0
A17: Bank Loan | B17: =SUMIFS(TXN_CREDIT,TXN_LEDGER,"Bank Loan",TXN_FLAG,"NEW")-SUMIFS(TXN_DEBIT,TXN_LEDGER,"Bank Loan",TXN_FLAG,"NEW") -> 0
A18: Capital Account | B18: =SUMIFS(TXN_CREDIT,TXN_LEDGER,"Capital Account",TXN_FLAG,"NEW")-SUMIFS(TXN_DEBIT,TXN_LEDGER,"Capital Account",TXN_FLAG,"NEW") -> 0
A19: Intercompany Balance (from sheet 12) | B19: =0 -> 0
A20: Total Liabilities & Capital | B20: =SUM(B15:B19) -> 0
A22: Add: Current Period Profit/(Loss) (link to P&L sheet's Net Profit cell) | B22: 0
A24: CHECK: Total Assets − (Total Liabilities & Capital) — must be 0 | B24: =B12-B20 -> 0

Sheet 19 Bank Reconstruction
A1: BANK RECONSTRUCTION
A2: Opening + Receipts − Payments = Closing, independently for both companies.
B5: Old Company | C5: New Company
A6: Opening Balance (enter manually from last audited books) | B6: 0 | C6: 0
A7: Total Receipts (Bank, this company's flagged vouchers) | B7: =SUMIFS(TXN_DEBIT,TXN_FLAG,"OLD",TXN_BANK,"<>") -> 185000 | C7: =SUMIFS(TXN_DEBIT,TXN_FLAG,"NEW",TXN_BANK,"<>") -> 45000
A8: Total Payments (Bank, this company's flagged vouchers) | B8: =SUMIFS(TXN_CREDIT,TXN_FLAG,"OLD",TXN_BANK,"<>") -> 950000 | C8: =SUMIFS(TXN_CREDIT,TXN_FLAG,"NEW",TXN_BANK,"<>") -> 0
A9: Closing Balance (computed) | B9: =B6+B7-B8 -> -765000 | C9: =C6+C7-C8 -> 45000
A11: Actual Bank Book / Statement Closing (enter from sheet 08/09 import, or bank statement) | B11: 0 | C11: 0
A12: Difference (must be 0) | B12: =B9-B11 -> -765000 | C12: =C9-C11 -> 45000
A15: HOW TO USE THIS SHEET
A16: 'TXN_BANK' matches against the free-text Bank/Cash column in Transaction Master — keep bank ledger names consistent (e.g. always 'HDFC Bank - Old Co').
A17: Enter each company's true opening balance once, from the last agreed books before the mixed period began.

Sheet 20 Cash Reconstruction
A1: CASH RECONSTRUCTION
A2: Opening + Receipts − Payments = Closing, independently for both companies.
B5: Old Company | C5: New Company
A6: Opening Balance (enter manually from last audited books) | B6: 0 | C6: 0
A7: Total Receipts (Cash, this company's flagged vouchers) | B7: =SUMIFS(TXN_DEBIT,TXN_FLAG,"OLD",TXN_CASH,"<>") -> 0 | C7: =SUMIFS(TXN_DEBIT,TXN_FLAG,"NEW",TXN_CASH,"<>") -> 0
A8: Total Payments (Cash, this company's flagged vouchers) | B8: =SUMIFS(TXN_CREDIT,TXN_FLAG,"OLD",TXN_CASH,"<>") -> 0 | C8: =SUMIFS(TXN_CREDIT,TXN_FLAG,"NEW",TXN_CASH,"<>") -> 0
A9: Closing Balance (computed) | B9: =B6+B7-B8 -> 0 | C9: =C6+C7-C8 -> 0
A11: Actual Cash Book / Statement Closing (enter from sheet 08/09 import, or bank statement) | B11: 0 | C11: 0
A12: Difference (must be 0) | B12: =B9-B11 -> 0 | C12: =C9-C11 -> 0
A15: HOW TO USE THIS SHEET
A16: 'TXN_CASH' matches against the free-text Bank/Cash column in Transaction Master — keep bank ledger names consistent (e.g. always 'HDFC Bank - Old Co').
A17: Enter each company's true opening balance once, from the last agreed books before the mixed period began.

Sheet 21 Stock Transfer
A1: STOCK TRANSFER — OLD CO SALE / NEW CO PURCHASE
A2: Rule 6: raw material stock moved Old→New is booked as an Old Co stock sale and a mirrored New Co stock purchase at the same value — no markup.
A5: Item | B5: Qty | C5: Unit | D5: Rate | E5: Value | F5: Old Co Entry | G5: New Co Entry | H5: Transfer Voucher No. | I5: Date
A6: 18mm MR Plywood - 8x4 | B6: 120 | C6: Sheet | D6: 2450 | E6: =B6*D6 -> 294000 | F6: Stock Sale (Credit) | G6: Stock Purchase (Debit) | H6: STK-XFER-001 | I6: 2026-01-15
A7: Laminate - Standard Finish | B7: 300 | C7: Sheet | D7: 950 | E7: =B7*D7 -> 285000 | F7: Stock Sale (Credit) | G7: Stock Purchase (Debit) | H7: STK-XFER-001 | I7: 2026-01-15
A8: TOTAL STOCK TRANSFER VALUE | E8: =SUM(E6:E7) -> 579000
A10: HOW TO USE THIS SHEET
A11: Add one row per item transferred. Value = Qty × Rate (formula, do not overtype).
A12: This total must be journaled twice in Transaction Master: once as Old Co's stock sale (credit Raw Material Stock, debit Intercompany), once as New Co's stock purchase (debit Raw Material Stock, credit Intercompany) — see sheet 26.
A13: No markup is applied — Rule 6 requires the same value on both sides.

Sheet 22 Project Cost Recovery
A1: PROJECT COST RECOVERY
A2: Direct cost New Co has incurred executing Old Co's ongoing projects, and how much has been recovered (Rule 3 & 5).
A5: Project | B5: Material | C5: Labour | D5: Transport | E5: Subcontract | F5: Total Direct Cost | G5: Recovered | H5: Pending Recovery
A6: Sandesh Residence | B6: =SUMIFS(TXN_DEBIT,TXN_PROJECT,A6,TXN_LEDGER,"Site Material Purchase") -> 185000 | C6: =SUMIFS(TXN_DEBIT,TXN_PROJECT,A6,TXN_LEDGER,"Site Labour Charges") -> 0 | D6: =SUMIFS(TXN_DEBIT,TXN_PROJECT,A6,TXN_LEDGER,"Site Transport") -> 0 | E6: =SUMIFS(TXN_DEBIT,TXN_PROJECT,A6,TXN_LEDGER,"Subcontract Charges") -> 0 | F6: =SUM(B6:E6) -> 185000 | G6: =SUMIFS(TXN_DEBIT,TXN_PROJECT,A6,TXN_RECOV,"Yes") -> 0 | H6: =F6-G6 -> 185000
A7: MC Enclave - Iqbal | B7: =SUMIFS(TXN_DEBIT,TXN_PROJECT,A7,TXN_LEDGER,"Site Material Purchase") -> 0 | C7: =SUMIFS(TXN_DEBIT,TXN_PROJECT,A7,TXN_LEDGER,"Site Labour Charges") -> 0 | D7: =SUMIFS(TXN_DEBIT,TXN_PROJECT,A7,TXN_LEDGER,"Site Transport") -> 0 | E7: =SUMIFS(TXN_DEBIT,TXN_PROJECT,A7,TXN_LEDGER,"Subcontract Charges") -> 0 | F7: =SUM(B7:E7) -> 0 | G7: =SUMIFS(TXN_DEBIT,TXN_PROJECT,A7,TXN_RECOV,"Yes") -> 0 | H7: =F7-G7 -> 0
A8: Villa 10, Moozhikkal - Shilpa Arun | B8: =SUMIFS(TXN_DEBIT,TXN_PROJECT,A8,TXN_LEDGER,"Site Material Purchase") -> 0 | C8: =SUMIFS(TXN_DEBIT,TXN_PROJECT,A8,TXN_LEDGER,"Site Labour Charges") -> 0 | D8: =SUMIFS(TXN_DEBIT,TXN_PROJECT,A8,TXN_LEDGER,"Site Transport") -> 0 | E8: =SUMIFS(TXN_DEBIT,TXN_PROJECT,A8,TXN_LEDGER,"Subcontract Charges") -> 0 | F8: =SUM(B8:E8) -> 0 | G8: =SUMIFS(TXN_DEBIT,TXN_PROJECT,A8,TXN_RECOV,"Yes") -> 0 | H8: =F8-G8 -> 0
A10: HOW TO USE THIS SHEET
A11: Project names must exactly match the 'Old Projects Master' list in sheet 01 Settings and the Project column in Transaction Master.
A12: Add a row per ongoing project. Extend the ledger-matching formulas (columns B-E) if you add more direct-cost ledger types in the Chart of Accounts.
A13: 'Recovered' pulls only vouchers marked Recovered From Old = Yes in Transaction Master — mark them as invoices are actually raised on Old Co.

Sheet 23 Receivable Split
A1: RECEIVABLE SPLIT
A2: Receivable balances by party, split Old vs New Co, from Transaction Master.
A5: Party | B5: Old Company Balance | C5: New Company Balance | D5: Total
A6: Sandesh | B6: =SUMIFS(TXN_DEBIT,TXN_CUSTOMER,A6,TXN_LEDGER,"Sundry Debtors",TXN_FLAG,"OLD")-SUMIFS(TXN_CREDIT,TXN_CUSTOMER,A6,TXN_LEDGER,"Sundry Debtors",TXN_FLAG,"OLD") -> 0 | C6: =SUMIFS(TXN_DEBIT,TXN_CUSTOMER,A6,TXN_LEDGER,"Sundry Debtors",TXN_FLAG,"NEW")-SUMIFS(TXN_CREDIT,TXN_CUSTOMER,A6,TXN_LEDGER,"Sundry Debtors",TXN_FLAG,"NEW") -> 0 | D6: =B6+C6 -> 0
A7: Mr. Iqbal | B7: =SUMIFS(TXN_DEBIT,TXN_CUSTOMER,A7,TXN_LEDGER,"Sundry Debtors",TXN_FLAG,"OLD")-SUMIFS(TXN_CREDIT,TXN_CUSTOMER,A7,TXN_LEDGER,"Sundry Debtors",TXN_FLAG,"OLD") -> 0 | C7: =SUMIFS(TXN_DEBIT,TXN_CUSTOMER,A7,TXN_LEDGER,"Sundry Debtors",TXN_FLAG,"NEW")-SUMIFS(TXN_CREDIT,TXN_CUSTOMER,A7,TXN_LEDGER,"Sundry Debtors",TXN_FLAG,"NEW") -> 0 | D7: =B7+C7 -> 0
A8: Shilpa Arun | B8: =SUMIFS(TXN_DEBIT,TXN_CUSTOMER,A8,TXN_LEDGER,"Sundry Debtors",TXN_FLAG,"OLD")-SUMIFS(TXN_CREDIT,TXN_CUSTOMER,A8,TXN_LEDGER,"Sundry Debtors",TXN_FLAG,"OLD") -> 0 | C8: =SUMIFS(TXN_DEBIT,TXN_CUSTOMER,A8,TXN_LEDGER,"Sundry Debtors",TXN_FLAG,"NEW")-SUMIFS(TXN_CREDIT,TXN_CUSTOMER,A8,TXN_LEDGER,"Sundry Debtors",TXN_FLAG,"NEW") -> 0 | D8: =B8+C8 -> 0
A9: TOTAL | B9: =SUM(B6:B8) -> 0 | C9: =SUM(C6:C8) -> 0 | D9: =SUM(D6:D8) -> 0
A11: HOW TO USE THIS SHEET
A12: Add every customer as a row (example customers shown in blue).
A13: Per Rule 1, receivables on ongoing projects should show entirely under 'Old Company Balance' — a nonzero New Company balance for an old-project customer is worth investigating.

Sheet 24 Payable Split
A1: PAYABLE SPLIT
A2: Payable balances by party, split Old vs New Co, from Transaction Master.
A5: Party | B5: Old Company Balance | C5: New Company Balance | D5: Total
A6: XYZ Timber Traders | B6: =SUMIFS(TXN_CREDIT,TXN_SUPPLIER,A6,TXN_LEDGER,"Sundry Creditors",TXN_FLAG,"OLD")-SUMIFS(TXN_DEBIT,TXN_SUPPLIER,A6,TXN_LEDGER,"Sundry Creditors",TXN_FLAG,"OLD") -> 0 | C6: =SUMIFS(TXN_CREDIT,TXN_SUPPLIER,A6,TXN_LEDGER,"Sundry Creditors",TXN_FLAG,"NEW")-SUMIFS(TXN_DEBIT,TXN_SUPPLIER,A6,TXN_LEDGER,"Sundry Creditors",TXN_FLAG,"NEW") -> 0 | D6: =B6+C6 -> 0
A7: ABC Hardware Suppliers | B7: =SUMIFS(TXN_CREDIT,TXN_SUPPLIER,A7,TXN_LEDGER,"Sundry Creditors",TXN_FLAG,"OLD")-SUMIFS(TXN_DEBIT,TXN_SUPPLIER,A7,TXN_LEDGER,"Sundry Creditors",TXN_FLAG,"OLD") -> 0 | C7: =SUMIFS(TXN_CREDIT,TXN_SUPPLIER,A7,TXN_LEDGER,"Sundry Creditors",TXN_FLAG,"NEW")-SUMIFS(TXN_DEBIT,TXN_SUPPLIER,A7,TXN_LEDGER,"Sundry Creditors",TXN_FLAG,"NEW") -> 0 | D7: =B7+C7 -> 0
A8: TOTAL | B8: =SUM(B6:B7) -> 0 | C8: =SUM(C6:C7) -> 0 | D8: =SUM(D6:D7) -> 0
A10: HOW TO USE THIS SHEET
A11: Add every supplier as a row (example suppliers shown in blue).
A12: Per Rule 1, receivables on ongoing projects should show entirely under 'Old Company Balance' — a nonzero New Company balance for an old-project customer is worth investigating.

Sheet 25 GST Reconciliation
A1: GST RECONCILIATION
A2: Output vs Input GST, split by company, from Transaction Master.
B5: Old Company | C5: New Company
A6: Output GST collected (Sales) | B6: =SUMIFS(TXN_GST,TXN_LEDGER,"Sales - Interior Projects",TXN_FLAG,"OLD") -> 171000 | C6: =SUMIFS(TXN_GST,TXN_LEDGER,"Sales - Interior Projects",TXN_FLAG,"NEW") -> 0
A7: Input GST paid (Material Purchase) | B7: =SUMIFS(TXN_GST,TXN_LEDGER,"Site Material Purchase",TXN_FLAG,"OLD") -> 9250 | C7: =SUMIFS(TXN_GST,TXN_LEDGER,"Site Material Purchase",TXN_FLAG,"NEW") -> 0
A8: Net GST Payable / (Credit Carried Forward) | B8: =B6-B7 -> 161750 | C8: =C6-C7 -> 0
A10: HOW TO USE THIS SHEET
A11: Extend the Output/Input rows if you add more Income or Direct Cost ledgers to the Chart of Accounts — copy the SUMIFS pattern with the new ledger name.
A12: Each company should file its own GSTR return once books are independent (post 11-Jul-2026) — this sheet is for internal reconciliation only, not a filing document.

Sheet 26 Adjustment Journals
A1: ADJUSTMENT JOURNALS
A2: Manual journal register for SHARED vouchers and anything flagged 'Adjustment Required = Yes' in Transaction Master. Nothing here is auto-applied — every line is a reviewed, approved decision.
A5: Ref Voucher No. | B5: Date | C5: Ledger | D5: Description of Adjustment | E5: Recommended Split (Old/New) | F5: Dr Company | G5: Cr Company | H5: Amount | I5: Approved By | J5: Status
A6: JV-0231 | B6: 2026-02-10 | C6: Site Material Purchase | D6: Direct material cost incurred by New Co bank for Sandesh (Old Co project) — reclassify as intercompany recoverable, not a New Co expense. | E6: 100% Old Co (per Rule 5) | F6: Intercompany - Old Co A/c | G6: Site Material Purchase | H6: 185000 | J6: Pending Review
A108: HOW TO USE THIS SHEET
A109: Workflow: filter sheet 11 Transaction Master by 'Adjustment Required? = Yes' or 'Flag = SHARED', then log each one here with a recommended treatment.
A110: Only journals with Status = Posted should be reflected back into Transaction Master (as a new dated correcting entry — never edit the original voucher row).
A111: This keeps a full audit trail: original entry, recommended fix, approval, and the correcting entry are all traceable.

Sheet 27 Reconciliation Dashboard
A1: RECONCILIATION DASHBOARD
A2: Single-page control panel — every difference below should read zero before the books are declared segregated.
A5: Check | B5: Result | C5: Notes
A6: Old Company TB Difference (Debit − Credit) | B6: ='13 Old Company TB'!D38 -> -765000 | C6: Must equal 0
A7: New Company TB Difference (Debit − Credit) | B7: ='14 New Company TB'!D38 -> 45000 | C7: Must equal 0
A8: Old Company Balance Sheet Check | B8: ='17 Old Company Balance Sheet'!B1000 -> 0 | C8: Link manually — see note
A9: New Company Balance Sheet Check | B9: ='18 New Company Balance Sheet'!B1000 -> 0 | C9: Link manually — see note
A10: Bank Difference — Old Co | B10: ='19 Bank Reconstruction'!B12 -> -765000 | C10: Reconstructed vs actual bank closing
